<p><strong>Подвиг 6.</strong> Имеется следующий фрагмент программы:</p>

<pre><code>try:
    x, y = map(float, input().split())
    d = x / y
except ZeroDivisionError:
    print('ZeroDivisionError')
except:
    print('except')
</code></pre>

<p>В каких случаях выполнение программы перейдет во второй блок except?</p>